<?xml version="1.0"?>
<robot name="cambot">
  <material name="black">
    <color rgba="0.0 0.0 0.0 1.0"/>
  </material>

  <material name="orange">
    <color rgba="1.0 0.4 0.0 1.0"/>
  </material>

  <material name="red">
    <color rgba="1.0 0.0 0.0 1.0"/>
  </material>

  <link name="base"/>

  <joint name="fixed" type="fixed">
    <parent link="base"/>
    <child link="link1"/>
  </joint>

  <link name="link1">
    <inertial>
      <origin xyz="0.0 0.0 1.0" rpy="0.0 0.0 0.0"/>
      <mass value="1.0"/>
    <inertia ixx="1.0" ixy="0.0" ixz="0.0" iyy="1.0" iyz="0.0" izz="1.0"/>
    </inertial>

    <visual>
      <origin xyz="0.0 0.0 1.0" rpy="0.0 0.0 0.0"/>
      <geometry>
        <box size="0.1 0.1 2.0"/>
      </geometry>
      <material name="orange"/>
    </visual>

    <collision>
      <origin xyz="0.0 0.0 1.0" rpy="0.0 0.0 0.0"/>
      <geometry>
        <box size="0.1 0.1 2.0"/>
      </geometry>
    </collision>
  </link>

  <joint name="joint1" type="continuous">
    <origin xyz="0.0 0.1 1.95" rpy="0.0 0.0 0.0"/>
    <parent link="link1"/>
    <child link="link2"/>
    <axis xyz="0.0 1.0 0.0"/>
    <dynamics damping="0.7"/>
  </joint>

  <link name="link2">
    <inertial>
      <origin xyz="0.0 0.0 0.45" rpy="0.0 0.0 0.0"/>
      <mass value="1.0"/>
      <inertia ixx="1.0" ixy="0.0" ixz="0.0" iyy="1.0" iyz="0.0" izz="1.0"/>
    </inertial>
    <visual>
      <origin xyz="0.0 0.0 0.45" rpy="0.0 0.0 0.0"/>
      <geometry>
        <box size="0.1 0.1 1.0"/>
      </geometry>
      <material name="black"/>
    </visual>
    <collision>
      <origin xyz="0.0 0.0 0.45" rpy="0.0 0.0 0.0"/>
      <geometry>
        <box size="0.1 0.1 1.0"/>
      </geometry>
    </collision>
  </link>

  <joint name="joint2" type="continuous">
    <parent link="link2"/>
    <child link="link3"/>
    <origin xyz="0.0 0.1 0.9" rpy="0.0 0.0 0.0"/>
    <axis xyz="0.0 1.0 0.0"/>
    <dynamics damping="0.7"/>
  </joint>

  <link name="link3">
    <inertial>
      <origin xyz="0.0 0.0 0.45" rpy="0.0 0.0 0.0"/>
      <mass value="1.0"/>
      <inertia ixx="1.0" ixy="0.0" ixz="0.0" iyy="1.0" iyz="0.0" izz="1.0"/>
    </inertial>
    <visual>
      <origin xyz="0.0 0.0 0.45" rpy="0.0 0.0 0.0"/>
      <geometry>
        <box size="0.1 0.1 1.0"/>
      </geometry>
      <material name="orange"/>
    </visual>
    <collision>
      <origin xyz="0.0 0.0 0.45" rpy="0.0 0.0 0.0"/>
      <geometry>
        <box size="0.1 0.1 1.0"/>
      </geometry>
    </collision>
  </link>

  <joint name="camera_joint" type="fixed">
    <origin xyz="0.05 0.0 0.975" rpy="0.0 0.0 0.0"/>
    <parent link="link3"/>
    <child link="camera_link"/>
    <axis xyz="0.0 1.0 0.0"/>
  </joint>

  <link name="camera_link">
    <inertial>
      <origin xyz="0.0 0.0 0.0" rpy="0.0 0.0 0.0"/>
      <mass value="1e-5"/>
      <inertia ixx="1e-6" ixy="0.0" ixz="0.0" iyy="1e-6" iyz="0.0" izz="1e-6"/>
    </inertial>
    <visual>
      <origin xyz="0.0 0.0 0.0" rpy="0.0 0.0 0.0"/>
      <geometry>
        <box size="0.05 0.05 0.05"/>
      </geometry>
      <material name="red"/>
    </visual>
    <collision>
      <origin xyz="0.0 0.0 0.0" rpy="0.0 0.0 0.0"/>
      <geometry>
        <box size="0.05 0.05 0.05"/>
      </geometry>
    </collision>
  </link>

  <joint name="camera_optical_joint" type="fixed">
    <origin xyz="0.0 0.0 0.0" rpy="-1.570796327 0.0 -1.570796327"/>
    <parent link="camera_link"/>
    <child link="camera_link_optical"/>
  </joint>

  <link name="camera_link_optical">
  </link>
</robot>
